[2025-05-14T11:40:00.759-0500] {local_task_job_runner.py:123} INFO - ::group::Pre task execution logs
[2025-05-14T11:40:00.783-0500] {taskinstance.py:2614} INFO - Dependencies all met for dep_context=non-requeueable deps ti=<TaskInstance: etl.merge_transformed_data scheduled__2025-05-13T00:00:00+00:00 [queued]>
[2025-05-14T11:40:00.798-0500] {taskinstance.py:2614} INFO - Dependencies all met for dep_context=requeueable deps ti=<TaskInstance: etl.merge_transformed_data scheduled__2025-05-13T00:00:00+00:00 [queued]>
[2025-05-14T11:40:00.799-0500] {taskinstance.py:2867} INFO - Starting attempt 1 of 2
[2025-05-14T11:40:00.820-0500] {taskinstance.py:2890} INFO - Executing <Task(PythonOperator): merge_transformed_data> on 2025-05-13 00:00:00+00:00
[2025-05-14T11:40:00.835-0500] {standard_task_runner.py:104} INFO - Running: ['airflow', 'tasks', 'run', 'etl', 'merge_transformed_data', 'scheduled__2025-05-13T00:00:00+00:00', '--job-id', '14', '--raw', '--subdir', 'DAGS_FOLDER/api.py', '--cfg-path', '/tmp/tmp9b8buxe0']
[2025-05-14T11:40:00.838-0500] {standard_task_runner.py:105} INFO - Job 14: Subtask merge_transformed_data
[2025-05-14T11:40:00.840-0500] {logging_mixin.py:190} WARNING - /home/jdd/ETL-Global-Road-Accidents/venv/lib/python3.12/site-packages/airflow/task/task_runner/standard_task_runner.py:70 DeprecationWarning: This process (pid=45123) is multi-threaded, use of fork() may lead to deadlocks in the child.
[2025-05-14T11:40:00.841-0500] {standard_task_runner.py:72} INFO - Started process 45210 to run task
[2025-05-14T11:40:00.889-0500] {task_command.py:467} INFO - Running <TaskInstance: etl.merge_transformed_data scheduled__2025-05-13T00:00:00+00:00 [running]> on host DESKTOP-43HC35D.
[2025-05-14T11:40:00.967-0500] {taskinstance.py:3134} INFO - Exporting env vars: AIRFLOW_CTX_DAG_OWNER='airflow' AIRFLOW_CTX_DAG_ID='etl' AIRFLOW_CTX_TASK_ID='merge_transformed_data' AIRFLOW_CTX_EXECUTION_DATE='2025-05-13T00:00:00+00:00' AIRFLOW_CTX_TRY_NUMBER='1' AIRFLOW_CTX_DAG_RUN_ID='scheduled__2025-05-13T00:00:00+00:00'
[2025-05-14T11:40:00.968-0500] {taskinstance.py:732} INFO - ::endgroup::
[2025-05-14T11:40:00.988-0500] {api.py:113} ERROR - ‚ùå Error en `task_merge_final()`: [Errno 2] No such file or directory: '/tmp/data/transformed_postgres_data.csv'
[2025-05-14T11:40:00.989-0500] {python.py:240} INFO - Done. Returned value was: None
[2025-05-14T11:40:00.996-0500] {taskinstance.py:341} INFO - ::group::Post task execution logs
[2025-05-14T11:40:00.997-0500] {taskinstance.py:353} INFO - Marking task as SUCCESS. dag_id=etl, task_id=merge_transformed_data, run_id=scheduled__2025-05-13T00:00:00+00:00, execution_date=20250513T000000, start_date=20250514T164000, end_date=20250514T164000
[2025-05-14T11:40:01.066-0500] {local_task_job_runner.py:266} INFO - Task exited with return code 0
[2025-05-14T11:40:01.089-0500] {taskinstance.py:3901} INFO - 0 downstream tasks scheduled from follow-on schedule check
[2025-05-14T11:40:01.091-0500] {local_task_job_runner.py:245} INFO - ::endgroup::
